Workbook

Sheet Tuition Averages
A3: Country | B3: Average Tuition per Country
A4: Australia | B4: 56534.5
A5: Canada | B5: 50774.75
A6: China | B6: 13475.6
A7: Denmark | B7: 47200
A8: France | B8: 39011.2
A9: Germany | B9: 16257.02
A10: Israel | B10: 20375
A11: Japan | B11: 14631.75
A12: Netherlands | B12: 235015
A13: Norway | B13: 70
A14: Singapore | B14: 38250
A15: South Korea | B15: 48000
... A21: Total | B21: 94900.001

Sheet CollegeRanking
A1: World Rank | B1: Institution | C1: Country | D1: State | E1: Tuition | F1: Acceptance Rate | G1: Class | H1: Country Rank | I1: Education Rank | J1: Employability Rank | K1: Faculty Rank | L1: Research Rank | M1: Score
A2: 1 | B2: Harvard University | C2: USA | D2: Massachusetts | E2: 334152 | F2: 0.04 | G2: Private | H2: 1 | I2: 1 | J2: 1 | K2: 1 | L2: 1 | M2: 100
A3: 2 | B3: Massachusetts Institute of Technology | C3: USA | D3: Massachusetts | E3: 240624 | F3: 0.041 | G3: Private | H3: 2 | I3: 4 | J3: 12 | K3: 2 | L3: 7 | M3: 96.7
A4: 3 | B4: Stanford University | C4: USA | D4: California | E4: 328648 | F4: 0.05 | G4: Private | H4: 3 | I4: 11 | J4: 4 | K4: 3 | L4: 2 | M4: 95.1
A5: 4 | B5: University of Cambridge | C5: United Kingdom | D5: England | E5: 71364 | F5: 0.21 | G5: Public | H5: 1 | I5: 3 | J5: 25 | K5: 4 | L5: 10 | M5: 94.1
A6: 5 | B6: University of Oxford | C6: United Kingdom | D6: England | E6: 131200 | F6: 0.175 | G6: Public | H6: 2 | I6: 7 | J6: 27 | K6: 9 | L6: 4 | M6: 93.3
A7: 6 | B7: Princeton University | C7: USA | D7: New Jersey | E7: 238410 | F7: 0.044 | G7: Private | H7: 4 | I7: 5 | J7: 15 | K7: 6 | L7: 79 | M7: 92.6
A8: 7 | B8: University of Chicago | C8: USA | D8: Illinois | E8: 257040 | F8: 0.065 | G8: Private | H8: 5 | I8: 8 | J8: 16 | K8: 21 | L8: 22 | M8: 92
A9: 8 | B9: Columbia University | C9: USA | D9: New York | E9: 278754 | F9: 0.17 | G9: Private | H9: 6 | I9: 12 | J9: 14 | K9: 10 | L9: 14 | M9: 91.5
A10: 9 | B10: University of Pennsylvania | C10: USA | D10: Pennsylvania | E10: 58620 | F10: 0.059 | G10: Private | H10: 7 | I10: 14 | J10: 8 | K10: 41 | L10: 11 | M10: 91.1
A11: 10 | B11: California Institute of Technology | C11: USA | D11: California | E11: 259524 | F11: 0.039 | G11: Private | H11: 8 | I11: 2 | J11: 104 | K11: 7 | L11: 80 | M11: 90.7
A12: 11 | B12: Yale University | C12: USA | D12: Connecticut | E12: 239800 | F12: 0.0435 | G12: Private | H12: 9 | I12: 6 | J12: 36 | K12: 12 | L12: 20 | M12: 0
A13: 12 | B13: University of California, Berkeley | C13: USA | D13: California | E13: 184032 | F13: 0.144 | G13: Public | H13: 10 | I13: 9 | J13: 59 | K13: 5 | L13: 16 | M13: 90.1
... A19: 18 | B19: University of California, Los Angeles | C19: USA | D19: California | E19: 54008 | F19: 0.108 | G19: Public | H19: 15 | I19: 42 | J19: 63 | K19: 17 | L19: 15 | M19: 88.6
A20: 19 | B20: PSL University | C20: France | D20: Paris | E20: 17040 | F20: Not Listed | G20: Public | H20: 1 | I20: 17 | J20: 30 | K20: 107 | L20: 86 | M20: 88.4
A21: 20 | B21: Duke University | C21: USA | D21: North Carolina | E21: 79380 | F21: 0.059 | G21: Private | H21: 16 | I21: 50 | J21: 48 | K21: 19 | L21: 25 | M21: 88.2
A22: 21 | B22: University College London | C22: United Kingdom | D22: London | E22: 101880 | F22: 0.3 | G22: Private | H22: 3 | I22: 33 | J22: 660 | K22: 15 | L22: 5 | M22: 88
A23: 22 | B23: University of Illinois at Urbana–Champaign | C23: USA | D23: Illinois | E23: 127895 | F23: 0.597 | G23: Public | H23: 17 | I23: 18 | J23: 139 | K23: 11 | L23: 73 | M23: 87.8
A24: 23 | B24: New York University | C24: USA | D24: NewYork | E24: 24328 | F24: 0.13 | G24: Private | H24: 18 | I24: 36 | J24: 43 | K24: 43 | L24: 46 | M24: 87.6
A25: 24 | B25: University of Toronto | C25: Canada | D25: Toronto | E25: 20400 | F25: 0.43 | G25: Public | H25: 1 | I25: 207 | J25: 159 | K25: 22 | L25: 3 | M25: 87.5
A26: 25 | B26: University of Washington | C26: USA | D26: Washington | E26: 122560 | F26: 0.535 | G26: Public | H26: 19 | I26: 71 | J26: 231 | K26: 25 | L26: 9 | M26: 87.3
A27: 26 | B27: Kyoto University | C27: Japan | D27: Kyoto | E27: 16400 | F27: 0.11 | G27: Public | H27: 2 | I27: 38 | J27: 33 | K27: 64 | L27: 75 | M27: 87.2
A28: 27 | B28: University of Wisconsin–Madison | C28: USA | D28: Wisconsin | E28: 109672 | F28: 0.49 | G28: Public | H28: 20 | I28: 34 | J28: 100 | K28: 30 | L28: 35 | M28: 87
A29: 28 | B29: McGill University | C29: Canada | D29: Quebec | E29: 44000 | F29: 0.463 | G29: Private | H29: 2 | I29: 25 | J29: 103 | K29: 44 | L29: 45 | M29: 86.9
A30: 29 | B30: ETH Zurich | C30: Switzerland | D30: Zurich | E30: 6080 | F30: 0.27 | G30: Private | H30: 1 | I30: 60 | J30: 89 | K30: 24 | L30: 42 | M30: 86.8
A31: 30 | B31: Imperial College London | C31: United Kingdom | D31: London | E31: 193752 | F31: 0.143 | G31: Private | H31: 4 | I31: 69 | J31: 117 | K31: 53 | L31: 17 | M31: 86.6
A32: 31 | B32: Seoul National University | C32: South Korea | D32: Seoul | E32: 48000 | F32: 0.17 | G32: Public | H32: 1 | I32: 336 | J32: 22 | K32: 150 | L32: 57 | M32: 86.5
... A35: 34 | B35: University of California, San Diego | C35: USA | D35: California | E35: 58800 | F35: 0.342 | G35: Public | H35: 22 | I35: 118 | J35: 1620 | K35: 13 | L35: 19 | M35: 86.1
A36: 35 | B36: University of California, San Francisco | C36: USA | D36: California | E36: 232888 | F36: 0.144 | G36: Public | H36: 23 | I36: - | J36: 1498 | K36: 14 | L36: 26 | M36: 86
A37: 36 | B37: University of Copenhagen | C37: Denmark | D37: Copenhagen | E37: 47200 | F37: 0.37 | G37: Public | H37: 1 | I37: 93 | J37: 383 | K37: 50 | L37: 27 | M37: 85.9
A38: 37 | B38: Karolinska Institute | C38: Sweden | D38: Solna | E38: 83520 | F38: 0.34 | G38: Public | H38: 1 | I38: 40 | J38: - | K38: 32 | L38: 60 | M38: 85.8
A39: 38 | B39: Sorbonne University | C39: France | D39: Paris | E39: 45744 | F39: 1 | G39: Private | H39: 3 | I39: 89 | J39: 309 | K39: 92 | L39: 18 | M39: 85.7
A40: 39 | B40: University of North Carolina at Chapel Hill | C40: USA | D40: North Carolina | E40: 99080 | F40: 0.204 | G40: Public | H40: 24 | I40: 85 | J40: 96 | K40: 78 | L40: 38 | M40: 85.6
A41: 40 | B41: King's College London | C41: United Kingdom | D41: London | E41: 50980 | F41: 0.29 | G41: Private | H41: 5 | I41: 58 | J41: 463 | K41: 29 | L41: 54 | M41: 85.5
A42: 41 | B42: Dartmouth College | C42: USA | D42: New Hampshire | E42: 326004 | F42: 0.062 | G42: Private | H42: 25 | I42: 54 | J42: 18 | K42: 102 | L42: 286 | M42: 85.4
A43: 42 | B43: Paris City University | C43: France | D43: Paris | E43: 47200 | F43: 0.11 | G43: Private | H43: 4 | I43: 240 | J43: 956 | K43: 58 | L43: 21 | M43: 85.3
A44: 43 | B44: Institut Polytechnique de Paris | C44: France | D44: Palaiseau | E44: 68912 | F44: 0.15 | G44: Private | H44: 5 | I44: 100 | J44: 9 | K44: 226 | L44: 344 | M44: 85.2
A45: 44 | B45: Ludwig Maximilian University of Munich | C45: Germany | D45: Munchen | E45: 50980 | F45: 0.1 | G45: Private | H45: 1 | I45: 59 | J45: 249 | K45: 54 | L45: 52 | M45: 85.1
A46: 45 | B46: University of Edinburgh | C46: United Kingdom | D46: Scotland | E46: 50980 | F46: 0.1 | G46: Private | H46: 6 | I46: 55 | J46: 452 | K46: 61 | L46: 49 | M46: 85
A47: 46 | B47: Washington University in St. Louis | C47: USA | D47: Missouri | E47: 247000 | F47: 0.13 | G47: Private | H47: 26 | I47: 133 | J47: 166 | K47: 36 | L47: 47 | M47: 85
...

Sheet Averages
A1: College Ranking Averages & Mode | L1: =VLOOKUP(1, CollegeRanking!A2:M101, 2, FALSE) -> Harvard University
A2: Key: | B2: AVERAGE | C2: MODE | D2: Quick Insight: The values in the tables below are rounded for readibility, values in the chart are exact.
A3: Group | B3: Tuition | C3: Acceptance Rate | D3: Class | E3: Country Rank | F3: Education Rank | G3: Employability Rank | H3: Faculty Rank | I3: Research Rank | J3: Score | K3: Country | L3: State
A4: Top 50 | B4: =AVERAGE(CollegeRanking!E2:E51) -> 116253.82 | C4: =AVERAGE(CollegeRanking!F2:F51) -> 0.2210102 | D4: Private | E4: =MODE(CollegeRanking!H2:H51) -> 1 | F4: =AVERAGE(CollegeRanking!I2:I51) -> 76.755102 | G4: =AVERAGE(CollegeRanking!J2:J51) -> 203.08163 | H4: =AVERAGE(CollegeRanking!K2:K51) -> 43.734694 | I4: =AVERAGE(CollegeRanking!L2:L51) -> 43.4 | J4: =AVERAGE(CollegeRanking!M2:M51) -> 86.424 | K4: USA: 22 | L4: California: 6
A5: Bottom 50 | B5: =AVERAGE(CollegeRanking!E52:E101) -> 73546.182 | C5: =AVERAGE(CollegeRanking!F52:F101) -> 0.34131429 | D5: Public | E5: =MODE(CollegeRanking!H52:H101) -> 2 | F5: =AVERAGE(CollegeRanking!I52:I101) -> 193.54348 | G5: =AVERAGE(CollegeRanking!J52:J101) -> 379.45652 | H5: =AVERAGE(CollegeRanking!K52:K101) -> 94.642857 | I5: =AVERAGE(CollegeRanking!L52:L101) -> 104.96 | J5: =AVERAGE(CollegeRanking!M52:M101) -> 83.012 | K5: USA: 27 | L5: Pennsylvania: 3
